Workbook

Sheet RECEIPT
A1: S.NO. | B1: DESCRIPTION | C1: UNIT | D1: 18/7/25 | E1: 8.8.25 | F1: 45889 | G1: 45890 | H1: 45899 | I1: 45903 | J1: 45906 | K1: 45915 | L1: 45917 | M1: 45919 | N1: 45920 | O1: 25 | P1: 45926 | Q1: TOTAL
A2: 1 | B2: Y 8MM | C2: PCS | Q2: =SUM(D2:P2) -> 0
A3: 2 | B3: Y 10MM | C3: PCS | Q3: =SUM(D3:P3) -> 0
A4: 3 | B4: WIRE CONNECTOR | C4: PCS | Q4: =SUM(D4:P4) -> 0
A5: 4 | B5: WINDER CONTROLLER | C5: PCS | Q5: =SUM(D5:P5) -> 0
A6: 5 | B6: WINDER CARD | C6: PCS | Q6: =SUM(D6:P6) -> 0
A7: 6 | B7: WELDING ROD MS | C7: PCS | I7: 2 | Q7: =SUM(D7:P7) -> 2
A8: 7 | B8: WELDING GOGGLE | C8: PCS | Q8: =SUM(D8:P8) -> 0
A9: 8 | B9: VERNIER CALIPER | C9: PCS | Q9: =SUM(D9:P9) -> 0
A10: 9 | B10: UPS FUSE 315A | C10: PCS | Q10: =SUM(D10:P10) -> 0
A11: 10 | B11: UPS FAN | C11: PCS | Q11: =SUM(D11:P11) -> 0
A12: 11 | B12: U TYPE THIMBLE 2.5MM | C12: PCS | Q12: =SUM(D12:P12) -> 0
A13: 12 | B13: U TYPE THIMBLE 1.5MM | C13: PCS | Q13: =SUM(D13:P13) -> 0
A14: 13 | B14: TUBE LIGHT DRIVER | C14: PCS | Q14: =SUM(D14:P14) -> 0
A15: 14 | B15: TPR FUSE 75A | C15: PCS | Q15: =SUM(D15:P15) -> 0
A16: 15 | B16: TPR FUSE 55A | C16: PCS | Q16: =SUM(D16:P16) -> 0
A17: 16 | B17: TPR FUSE 50A | C17: PCS | Q17: =SUM(D17:P17) -> 0
A18: 17 | B18: TPR FUSE 35A | C18: PCS | Q18: =SUM(D18:P18) -> 0
A19: 18 | B19: TPR 40A | C19: PCS | Q19: =SUM(D19:P19) -> 0
... A21: 20 | B21: TIMER ON DELAY | C21: PCS | Q21: =SUM(D21:P21) -> 0
A22: 21 | B22: TIMER DT 60 S | C22: PCS | D22: 2 | Q22: =SUM(D22:P22) -> 2
A23: 22 | B23: TIMER AT8N | C23: PCS | Q23: =SUM(D23:P23) -> 0
A24: 23 | B24: TIMER 55ES-P8-230 | C24: PCS | Q24: =SUM(D24:P24) -> 0
A25: 24 | B25: THIMBLE 150MM | C25: PCS | D25: 6 | Q25: =SUM(D25:P25) -> 6
A26: 25 | B26: THERMOCOUPLE P TYPE | C26: PCS | Q26: =SUM(D26:P26) -> 0
A27: 26 | B27: THERMOCOUPLE K TYPE | C27: PCS | Q27: =SUM(D27:P27) -> 0
A28: 27 | B28: THERMOCOUPLE 5MTR | C28: PCS | Q28: =SUM(D28:P28) -> 0
A29: 28 | B29: THERMOCOUPLE 3MTR | C29: PCS | Q29: =SUM(D29:P29) -> 0
A30: 29 | B30: TEMP.CONTROLLER UTC 122 | C30: PCS | Q30: =SUM(D30:P30) -> 0
A31: 30 | B31: TEMP.CONTROLLER TK4M-14RN | C31: PCS | Q31: =SUM(D31:P31) -> 0
A32: 31 | B32: TEMP.CONTROLLER DX 9 | C32: PCS | Q32: =SUM(D32:P32) -> 0
A33: 32 | B33: TEE 8MM | C33: PCS | Q33: =SUM(D33:P33) -> 0
A34: 33 | B34: TEE 6MM | C34: PCS | Q34: =SUM(D34:P34) -> 0
A35: 34 | B35: TEE 12MM | C35: PCS | Q35: =SUM(D35:P35) -> 0
A36: 35 | B36: TEE 1/2X10 | C36: PCS | Q36: =SUM(D36:P36) -> 0
A37: 36 | B37: TAPER SLEEVE H 315 | C37: PCS | Q37: =SUM(D37:P37) -> 0
A38: 37 | B38: TAPE DISPENSOR | C38: PCS | G38: 2 | J38: 4 | Q38: =SUM(D38:P38) -> 6
A39: 38 | B39: TAFLON TAPE | C39: PCS | D39: 10 | Q39: =SUM(D39:P39) -> 10
A40: 39 | B40: SWITCH 6A | C40: PCS | Q40: =SUM(D40:P40) -> 0
A41: 40 | B41: SWITCH 16A | C41: PCS | Q41: =SUM(D41:P41) -> 0
...

Sheet ISSUE
A1: S.NO. | B1: DESCRIPTION | C1: UNIT | D1: 2.7.25 | E1: 3.7.25 | F1: 4.7.25 | G1: 15.7.25 | H1: 45854 | I1: 18 | J1: 19.07.25 | K1: 21.07.25 | L1: 23.07.25 | M1: 24.07.25 | N1: 26.07.25 | O1: 27 | P1: 30 | Q1: 31 | R1: 45665 | S1: 2.8 | T1: 5.8 | U1: 6.8 | V1: 7.8 | W1: 8.8 | X1: 10 | Y1: 11 | Z1: 13 | AA1: 14 | AB1: 16 | AC1: 18 | AD1: 19 | AE1: 20 | AF1: 21 | AG1: 22 | AH1: 23 | AI1: 26 | AJ1: 27 | AK1: 28 | AL1: 29 | AM1: 30 | AN1: 31 | AO1: 45901 | AP1: 3 | AQ1: 4 | AR1: 7 | AS1: 9 | AT1: 12 | AU1: 14 | AV1: 15 | AW1: 19 | AX1: 20 | AY1: 21 | AZ1: 22 | BA1: 25 | BB1: 29 | BC1: TOTAL | BD1: 45931 | BE1: 3 | BF1: 4 | BG1: 5
A2: 1 | B2: =RECEIPT!B2 -> Y 8MM | C2: PCS | BC2: =SUM(D2:BB2) -> 0
A3: 2 | B3: =RECEIPT!B3 -> Y 10MM | C3: PCS | BC3: =SUM(D3:BB3) -> 0
A4: 3 | B4: =RECEIPT!B4 -> WIRE CONNECTOR | C4: PCS | BC4: =SUM(D4:BB4) -> 0
A5: 4 | B5: =RECEIPT!B5 -> WINDER CONTROLLER | C5: PCS | BC5: =SUM(D5:BB5) -> 0
A6: 5 | B6: =RECEIPT!B6 -> WINDER CARD | C6: PCS | O6: 1 | BC6: =SUM(D6:BB6) -> 1
A7: 6 | B7: =RECEIPT!B7 -> WELDING ROD MS | C7: PCK | AP7: 1 | AU7: 1 | AZ7: 1 | BC7: =SUM(D7:BB7) -> 3
A8: 7 | B8: =RECEIPT!B8 -> WELDING GOGGLE | C8: PCS | BC8: =SUM(D8:BB8) -> 0
A9: 8 | B9: =RECEIPT!B9 -> VERNIER CALIPER | C9: PCS | BC9: =SUM(D9:BB9) -> 0
A10: 9 | B10: =RECEIPT!B10 -> UPS FUSE 315A | C10: PCS | BC10: =SUM(D10:BB10) -> 0
A11: 10 | B11: =RECEIPT!B11 -> UPS FAN | C11: PCS | BC11: =SUM(D11:BB11) -> 0
A12: 11 | B12: =RECEIPT!B12 -> U TYPE THIMBLE 2.5MM | C12: PCS | R12: 6 | BC12: =SUM(D12:BB12) -> 6
A13: 12 | B13: =RECEIPT!B13 -> U TYPE THIMBLE 1.5MM | C13: PCS | BC13: =SUM(D13:BB13) -> 0
A14: 13 | B14: =RECEIPT!B14 -> TUBE LIGHT DRIVER | C14: PCS | Y14: 3 | BC14: =SUM(D14:BB14) -> 3
A15: 14 | B15: =RECEIPT!B15 -> TPR FUSE 75A | C15: PCS | BC15: =SUM(D15:BB15) -> 0
A16: 15 | B16: =RECEIPT!B16 -> TPR FUSE 55A | C16: PCS | BC16: =SUM(D16:BB16) -> 0
A17: 16 | B17: =RECEIPT!B17 -> TPR FUSE 50A | C17: PCS | BC17: =SUM(D17:BB17) -> 0
A18: 17 | B18: =RECEIPT!B18 -> TPR FUSE 35A | C18: PCS | BC18: =SUM(D18:BB18) -> 0
A19: 18 | B19: =RECEIPT!B19 -> TPR 40A | C19: PCS | BC19: =SUM(D19:BB19) -> 0
A20: 19 | B20: =RECEIPT!B20 -> TOGGLE SWITCH 15A | C20: PCS | K20: 1 | Q20: 2 | BC20: =SUM(D20:BB20) -> 3
A21: 20 | B21: =RECEIPT!B21 -> TIMER ON DELAY | C21: PCS | BC21: =SUM(D21:BB21) -> 0
A22: 21 | B22: =RECEIPT!B22 -> TIMER DT 60 S | C22: PCS | P22: 2 | BC22: =SUM(D22:BB22) -> 2
A23: 22 | B23: =RECEIPT!B23 -> TIMER AT8N | C23: KG | BC23: =SUM(D23:BB23) -> 0
A24: 23 | B24: =RECEIPT!B24 -> TIMER 55ES-P8-230 | C24: PCS | BC24: =SUM(D24:BB24) -> 0
A25: 24 | B25: =RECEIPT!B25 -> THIMBLE 150MM | C25: PCS | P25: 6 | BC25: =SUM(D25:BB25) -> 6
A26: 25 | B26: =RECEIPT!B26 -> THERMOCOUPLE P TYPE | C26: PCS | BC26: =SUM(D26:BB26) -> 0
A27: 26 | B27: =RECEIPT!B27 -> THERMOCOUPLE K TYPE | C27: PCS | BC27: =SUM(D27:BB27) -> 0
A28: 27 | B28: =RECEIPT!B28 -> THERMOCOUPLE 5MTR | C28: PCS | BC28: =SUM(D28:BB28) -> 0
A29: 28 | B29: =RECEIPT!B29 -> THERMOCOUPLE 3MTR | C29: PCS | BC29: =SUM(D29:BB29) -> 0
A30: 29 | B30: =RECEIPT!B30 -> TEMP.CONTROLLER UTC 122 | C30: PCS | BC30: =SUM(D30:BB30) -> 0
A31: 30 | B31: =RECEIPT!B31 -> TEMP.CONTROLLER TK4M-14RN | C31: PCS | BC31: =SUM(D31:BB31) -> 0
A32: 31 | B32: =RECEIPT!B32 -> TEMP.CONTROLLER DX 9 | C32: PCS | BC32: =SUM(D32:BB32) -> 0
A33: 32 | B33: =RECEIPT!B33 -> TEE 8MM | C33: PCS | BC33: =SUM(D33:BB33) -> 0
A34: 33 | B34: =RECEIPT!B34 -> TEE 6MM | C34: PCS | BC34: =SUM(D34:BB34) -> 0
A35: 34 | B35: =RECEIPT!B35 -> TEE 12MM | C35: PCS | BC35: =SUM(D35:BB35) -> 0
A36: 35 | B36: =RECEIPT!B36 -> TEE 1/2X10 | C36: PCS | BC36: =SUM(D36:BB36) -> 0
A37: 36 | B37: =RECEIPT!B37 -> TAPER SLEEVE H 315 | C37: PCS | BC37: =SUM(D37:BB37) -> 0
A38: 37 | B38: =RECEIPT!B38 -> TAPE DISPENSOR | C38: PCS | AE38: 1 | AH38: 1 | AX38: 1 | BA38: 1 | BC38: =SUM(D38:BB38) -> 4
A39: 38 | B39: =RECEIPT!B39 -> TAFLON TAPE | C39: PCS | N39: 1 | O39: 1 | T39: 1 | AE39: 2 | AF39: 1 | AK39: 2 | AS39: 2 | AU39: 1 | BC39: =SUM(D39:BB39) -> 11
A40: 39 | B40: =RECEIPT!B40 -> SWITCH 6A | C40: PCS | BC40: =SUM(D40:BB40) -> 0
...

Sheet BALANCE
A1: S.NO. | B1: DESCRIPTION | C1: UNIT | D1: OPENING | E1: RECEIPT | F1: ISSUE | G1: BALANCE
A2: 1 | B2: =RECEIPT!B2 -> Y 8MM | C2: PCS | D2: 8 | E2: =RECEIPT!Q2 -> 0 | F2: =ISSUE!BC2 -> 0 | G2: =+D2+E2-F2 -> 8
A3: 2 | B3: =RECEIPT!B3 -> Y 10MM | C3: PCS | D3: 10 | E3: =RECEIPT!Q3 -> 0 | F3: =ISSUE!BC3 -> 0 | G3: =+D3+E3-F3 -> 10
A4: 3 | B4: =RECEIPT!B4 -> WIRE CONNECTOR | C4: PCS | D4: 4 | E4: =RECEIPT!Q4 -> 0 | F4: =ISSUE!BC4 -> 0 | G4: =+D4+E4-F4 -> 4
A5: 4 | B5: =RECEIPT!B5 -> WINDER CONTROLLER | C5: PCS | D5: 1 | E5: =RECEIPT!Q5 -> 0 | F5: =ISSUE!BC5 -> 0 | G5: =+D5+E5-F5 -> 1
A6: 5 | B6: =RECEIPT!B6 -> WINDER CARD | C6: PCS | D6: 1 | E6: =RECEIPT!Q6 -> 0 | F6: =ISSUE!BC6 -> 1 | G6: =+D6+E6-F6 -> 0
A7: 6 | B7: =RECEIPT!B7 -> WELDING ROD MS | C7: PKT | D7: 1 | E7: =RECEIPT!Q7 -> 2 | F7: =ISSUE!BC7 -> 3 | G7: =+D7+E7-F7 -> 0
A8: 7 | B8: =RECEIPT!B8 -> WELDING GOGGLE | C8: PCS | D8: 5 | E8: =RECEIPT!Q8 -> 0 | F8: =ISSUE!BC8 -> 0 | G8: =+D8+E8-F8 -> 5
A9: 8 | B9: =RECEIPT!B9 -> VERNIER CALIPER | C9: PCS | D9: 2 | E9: =RECEIPT!Q9 -> 0 | F9: =ISSUE!BC9 -> 0 | G9: =+D9+E9-F9 -> 2
A10: 9 | B10: =RECEIPT!B10 -> UPS FUSE 315A | C10: PCS | D10: 2 | E10: =RECEIPT!Q10 -> 0 | F10: =ISSUE!BC10 -> 0 | G10: =+D10+E10-F10 -> 2
A11: 10 | B11: =RECEIPT!B11 -> UPS FAN | C11: PCS | D11: 2 | E11: =RECEIPT!Q11 -> 0 | F11: =ISSUE!BC11 -> 0 | G11: =+D11+E11-F11 -> 2
A12: 11 | B12: =RECEIPT!B12 -> U TYPE THIMBLE 2.5MM | C12: PCS | D12: 150 | E12: =RECEIPT!Q12 -> 0 | F12: =ISSUE!BC12 -> 6 | G12: =+D12+E12-F12 -> 144
A13: 12 | B13: =RECEIPT!B13 -> U TYPE THIMBLE 1.5MM | C13: PCS | D13: 200 | E13: =RECEIPT!Q13 -> 0 | F13: =ISSUE!BC13 -> 0 | G13: =+D13+E13-F13 -> 200
... A83: 82 | B83: =RECEIPT!B83 -> PU CONNECTOR 1/4" X 8 | C83: PCS | D83: 5 | E83: =RECEIPT!Q83 -> 0 | F83: =ISSUE!BC83 -> 1 | G83: =+D83+E83-F83 -> 4
A84: 83 | B84: =RECEIPT!B84 -> PU CONNECTOR 1/4" X 12 | C84: PCS | D84: 4 | E84: =RECEIPT!Q84 -> 0 | F84: =ISSUE!BC83 -> 1 | G84: =+D84+E84-F84 -> 3
A85: 84 | B85: =RECEIPT!B85 -> PU CONNECTOR 1/4" X 10 | C85: PCS | D85: 15 | E85: =RECEIPT!Q85 -> 0 | F85: =ISSUE!BC85 -> 0 | G85: =+D85+E85-F85 -> 15
A86: 85 | B86: =RECEIPT!B86 -> PU CONNECTOR 1/2" X 12 | C86: PCS | D86: 10 | E86: =RECEIPT!Q86 -> 0 | F86: =ISSUE!BC86 -> 2 | G86: =+D86+E86-F86 -> 8
A87: 86 | B87: =RECEIPT!B87 -> PU CONNECTOR 1/2" X 10 | C87: PCS | D87: 22 | E87: =RECEIPT!Q87 -> 0 | F87: =ISSUE!BC87 -> 0 | G87: =+D87+E87-F87 -> 22
A88: 87 | B88: =RECEIPT!B88 -> MPCB 4-6.3 AMP | C88: PCS | D88: 0 | E88: =RECEIPT!Q88 -> 2 | F88: =ISSUE!BC88 -> 0 | G88: =+D88+E88-F88 -> 2
A89: 88 | B89: =RECEIPT!B89 -> POWER SUPPLY 24V | C89: PCS | D89: 2 | E89: =RECEIPT!Q89 -> 0 | F89: =ISSUE!BC89 -> 0 | G89: =+D89+E89-F89 -> 2
A90: 89 | B90: =RECEIPT!B90 -> POWER FACTOR CONTACTOR MOC 50KVA | C90: PCS | D90: 2 | E90: =RECEIPT!Q90 -> 0 | F90: =ISSUE!BC90 -> 1 | G90: =+D90+E90-F90 -> 1
A91: 90 | B91: =RECEIPT!B91 -> POWER FACTOR CONTACTOR MOC 25KVA | C91: PCS | D91: 4 | E91: =RECEIPT!Q91 -> 0 | F91: =ISSUE!BC91 -> 0 | G91: =+D91+E91-F91 -> 4
A92: 91 | B92: =RECEIPT!B92 -> POWER FACTOR CAPACITOR 25KVA | C92: PCS | D92: 2 | E92: =RECEIPT!Q92 -> 0 | F92: =ISSUE!BC92 -> 0 | G92: =+D92+E92-F92 -> 2
A93: 92 | B93: =RECEIPT!B93 -> POWER FACTOR CAPACITOR 25 KVAR | C93: PCS | D93: 1 | E93: =RECEIPT!Q93 -> 0 | F93: =ISSUE!BC93 -> 0 | G93: =+D93+E93-F93 -> 1
A94: 93 | B94: =RECEIPT!B94 -> POWER FACTOR CAPACITOR 20 KVAR | C94: PCS | D94: 1 | E94: =RECEIPT!Q94 -> 0 | F94: =ISSUE!BC94 -> 0 | G94: =+D94+E94-F94 -> 1
A95: 94 | B95: =RECEIPT!B95 -> POWER FACTOR CAPACITOR 10KVA | C95: PCS | D95: 1 | E95: =RECEIPT!Q95 -> 0 | F95: =ISSUE!BC95 -> 0 | G95: =+D95+E95-F95 -> 1
A96: 95 | B96: =RECEIPT!B96 -> POTENTIO METER B202K | C96: PKT | D96: 4 | E96: =RECEIPT!Q96 -> 0 | F96: =ISSUE!BC96 -> 0 | G96: =+D96+E96-F96 -> 4
... A99: 98 | B99: =RECEIPT!B99 -> POTENTIO METER 250K | C99: PCS | D99: 6 | E99: =RECEIPT!Q99 -> 0 | F99: =ISSUE!BC99 -> 0 | G99: =+D99+E99-F99 -> 6
A100: 99 | B100: =RECEIPT!B100 -> POTENTIO METER 1K | C100: PCS | E100: =RECEIPT!Q100 -> 0 | F100: =ISSUE!BC100 -> 1 | G100: =+D100+E100-F100 -> #VALUE!
A101: 100 | B101: =RECEIPT!B101 -> POTENTIO METER 10K | C101: PCS | D101: 10 | E101: =RECEIPT!Q101 -> 2 | F101: =ISSUE!BC101 -> 0 | G101: =+D101+E101-F101 -> 12
A102: 101 | B102: =RECEIPT!B102 -> POTENTIO METER 100K | C102: PCS | D102: 5 | E102: =RECEIPT!Q102 -> 0 | F102: =ISSUE!BC102 -> 0 | G102: =+D102+E102-F102 -> 5
A103: 102 | B103: =RECEIPT!B103 -> PNEUMATIC CYLINDER 80X160 | C103: PCS | D103: 2 | E103: =RECEIPT!Q103 -> 0 | F103: =ISSUE!BC103 -> 0 | G103: =+D103+E103-F103 -> 2
A104: 103 | B104: =RECEIPT!B104 -> PNEUMATIC CYLINDER 63X50 | C104: PCS | D104: 1 | E104: =RECEIPT!Q104 -> 0 | F104: =ISSUE!BC104 -> 0 | G104: =+D104+E104-F104 -> 1
A105: 104 | B105: =RECEIPT!B105 -> PLASTIC TAP | C105: PCS | D105: 5 | E105: =RECEIPT!Q105 -> 2 | F105: =ISSUE!BC105 -> 1 | G105: =+D105+E105-F105 -> 6
A106: 105 | B106: =RECEIPT!B106 -> PIPE THIMBLE 5MM | C106: PCS | D106: 73 | E106: =RECEIPT!Q106 -> 0 | F106: =ISSUE!BC106 -> 0 | G106: =+D106+E106-F106 -> 73
A107: 106 | B107: =RECEIPT!B107 -> PIPE THIMBLE 1.5MM | C107: PCS | D107: 200 | E107: =RECEIPT!Q107 -> 0 | F107: =ISSUE!BC107 -> 0 | G107: =+D107+E107-F107 -> 200
A108: 107 | B108: =RECEIPT!B108 -> PIPE M/C GLASS HEATER 500W/230V P | C108: PCS | D108: 23 | E108: =RECEIPT!Q108 -> 0 | F108: =ISSUE!BC108 -> 1 | G108: =+D108+E108-F108 -> 22
A109: 108 | B109: =RECEIPT!B109 -> PIPE M/C GLASS HEATER 500W/230V GI | C109: PCS | D109: 14 | E109: =RECEIPT!Q109 -> 0 | F109: =ISSUE!BC109 -> 1 | G109: =+D109+E109-F109 -> 13
A110: 109 | B110: =RECEIPT!B110 -> PIPE M/C GLASS HEATER 500W/230V D | C110: PCS | D110: 3 | E110: =RECEIPT!Q110 -> 0 | F110: =ISSUE!BC110 -> 0 | G110: =+D110+E110-F110 -> 3
A111: 110 | B111: =RECEIPT!B111 -> PHOTO SENSOR SET | C111: PCS | D111: 1 | E111: =RECEIPT!Q111 -> 0 | F111: =ISSUE!BC111 -> 0 | G111: =+D111+E111-F111 -> 1
...
